Workbook

Sheet 阶段目标与项目
A1: 阶段 | B1: 阶段目标 | C1: 验收项目 | D1: 验收标准
A2: 阶段1 环境与Python | B2: 稳定Mac开发环境；能独立写Python脚本和FastAPI接口 | C2: Console订单管理器 + FastAPI小服务 | D2: 能从终端运行；JSON保存/读取；至少3个REST接口；README写清启动方式
A3: 阶段2 LLM API基础 | B3: 掌握模型API、Prompt、上下文、流式输出和结构化输出 | C3: AI Console助手 / Java异常分析助手 | D3: 支持连续提问；结构化JSON输出；Streaming；异常/超时处理
A4: 阶段3 Tool Calling | B4: 让模型可靠调用数据库/API工具完成业务查询 | C4: 订单退款失败分析助手 | D4: 至少4个Tools；能自动选工具；支持连续工具调用；有调用日志和错误处理
A5: 阶段4 RAG知识库 后面都是核心 | B5: 掌握Embedding、pgvector、检索、Rerank和来源引用 | C5: 本地企业知识库Demo | D5: 支持PDF/Word/Excel/MD；回答带来源；10个测试问题；资料不足时不乱答
A6: 阶段5 Agent与工作流 | B6: 掌握LangGraph、State、Memory、Workflow和人工介入 | C6: 订单问题诊断Agent | D6: 自动查订单/支付/退款/RAG；支持失败分支、最大步数、Checkpoint和人工确认
A7: 阶段6 MCP | B7: 能编写MCP Server并把业务能力暴露为Tools | C7: 数据库 + 文档检索 MCP Server | D7: 至少4个MCP Tools；参数校验；只读安全边界；Agent可通过MCP调用
A8: 阶段7 Java AI整合 | B8: 用Spring AI把LLM、Tool、RAG接入Spring Boot | C8: Spring Boot AI服务 | D8: Java完成LLM调用、Tool Calling、RAG；可调用Python Agent；统一REST接口
A9: 阶段8 综合项目 | B9: 完成可演示、可写进简历的企业AI Agent项目 | C9: Enterprise AI Agent Platform | D9: 按README启动；3个核心业务场景；权限/日志/超时；10个验收问题；5分钟演示
A10: AI平台/算法工程 阶段9 模型微调与评测 | B10: 掌握微调数据构建、SFT、LoRA/QLoRA、P-Tuning、对齐原理和模型评测 | C10: Qwen小模型微调 + RAG + Agent | D10: 完成可重复训练；保存和部署Adapter；使用固定测试集比较微调前后效果；README记录参数与限制
A11: AI平台/算法工程 阶段10 企业部署、安全与架构 | B11: 掌握模型服务化、推理性能、AI安全、LLMOps、Docker/K8s基础和架构设计 | C11: 航空运价规则智能审核平台 | D11: Docker可启动；包含Tool权限、人工确认、Trace、评测、压测、降级和架构评审文档
A12: 【可选】阶段11 AI平台与推理优化 | B12: 了解分布式训练、模型压缩、推理加速、GPU调度和推理集群建设 | C12: AI训练与推理平台设计方案 | D12: 说明DDP/FSDP/DeepSpeed、量化/剪枝/蒸馏、ONNX/TensorRT、GPU调度、灰度与回滚方案
B14: 阶段9：重点做 Transformers、Tokenizer、SFT、LoRA/QLoRA、PEFT、Qwen LoRA、评测、接入 Ollama/vLLM、微调+RAG+Agent DPO、RLHF、Reward Model、P-Tuning、Prefix Tuning 可以先理解原理，不必全实操。
A16: 总结： | D16: 核心流程：用户问题->查询改写/意图识别->元数据过滤(打标设计)->召回（向量检索+BM25关键词检索）->结果合并去重->融合（线性加权融合/rrf）->得到候选top-k->Cross-encoder精排->上下文截断压缩->构造提示词->LLM CrossEncoder是把query和文档拼接成一个序列，一起送入transformer模型里，模型内部通过注意力机制得到一个相关分数。 扩展：注意力机制：比如去图书馆找报销的报告，笨办法是全部读一遍。注意力就是query，报销标准是什么。Key，财务？HR？差旅。value：书的内容。用query和key比对，匹配高就重点读。这里就是通过softmax得到一组权重（0~1，加起来是1）。然后用权重加权value。 注意力机制 = 带着问题（Query）去扫一遍所有信息（Key），按相关度（softmax 权重）把内容（Value）加权综合。 transformer就是并行执行（多头注意力），让模型从不同角度看句子。是架构。 在这之前还需要chunk数据。
A17: 1.pgvector是pgsql的插件
A18: 2.检索内容注入Prompt生成回答流程：用户问题 → 查询改写 / 意图识别 → 权限与元数据过滤→ 查询 Embedding→ pgvector Top-K 检索 → 可选：关键词检索 BM25→ 合并去重→ Rerank 重排→ 截断 / 压缩 Context → 拼接带编号的 Context→ 构造 Prompt→ 调用 DeepSeek→ 引用校验 / 拒答检查 → 最终回答→ 日志与评估 意图识别区分 order / refund / rule / general，偏业务，简单路由。 查询改写：将“退款有什么规则？”改写为“退款规则”，且精确匹配时抽取实体 引用编号 Prompt：防止多跳，方便debug和追溯。 关键词检索 BM25是用来打分的。给一个查询和一堆文档来打分。 正常还有向量打分。然后可以用rrf来进行融合打分，判断哪一个更好用。 用tsvector全文索引也可以，只是中文分词不好，会吧一句话当一个词。 es有ik分词。长文本在考虑es集群。向量检索 + 关键词检索就是最终混合检索。
A24: 3.元数据预过滤：一般来说提前过滤一个类型字段。扩展：打标系统，需要一个类型，一个子类型扩展。在加一个文档类型。等于是2个维度的过滤。如果不够，后台运营加上tags。选other类型就是机器分不出来，走人工流程。置信度就是机器打分，打分太低进入人工审核。设计原则：同一模块同一 doc_type 下向量检索噪声大到影响回答质量时，加tags扩展，在此之前，所有额外字段都是负债。 备注：置信度可用softmax+temperature scaling 实现。softmax把分数变成 加起来等于1 的权重。
D26: 注意力机制 = 带着问题（Query）去扫一遍所有信息（Key），按相关度（softmax 权重）把内容（Value）加权综合。

Sheet 每日学习计划
A1: 序号 | B1: 日期 | C1: 星期 | D1: 阶段 | E1: 每日任务 | F1: 计划时长 | G1: 状态 | H1: 实际时长(h) | I1: 完成度 | J1: 学习笔记/问题 | K1: 阶段目标 / 项目验收 | L1: 备注
A2: 1 | B2: 46251 | C2: 周一 | D2: 阶段1 环境与Python | E2: 检查Mac：Homebrew、Git、VS Code、IntelliJ版本；建立环境检查记录 | F2: 2–3小时 | G2: 已完成 | I2: =IF(G2="已完成",1,IF(G2="进行中",0.5,0)) -> 1 | K2: 51
A3: 2 | B3: 46252 | C3: 周二 | D3: 阶段1 环境与Python | E3: 安装/确认Python 3.11或3.12；弄清python3、pip3和PATH | F3: 2–3小时 | G3: 已完成 | I3: =IF(G3="已完成",1,IF(G3="进行中",0.5,0)) -> 1 | J3: Python 3.11.9 pip 24.0 / Python 3.11。3.96和conda还在。
A4: 3 | B4: 46253 | C4: 周三 | D4: 阶段1 环境与Python | E4: 创建~/ai-study；建立venv；写requirements.txt | F4: 2–3小时 | G4: 已完成 | I4: =IF(G4="已完成",1,IF(G4="进行中",0.5,0)) -> 1 | J4: 1.建立一个venv的虚拟环境，相关项目在这个虚拟目录下，起隔离作用。激活。 2.准备安装的 Python 库。升级虚拟目录pip和执行环境。这里只是在虚拟目录下，pip就是maven的作用，或者Homebrew的作用。（终端激活默认就到可以，可以关闭） | K4: 1.创建python虚拟环境：python3.11 -m venv .venv 2.激活：source .venv/bin/activate 3.准备安装的 Python 库 cat > requirements.txt <<'EOF' openai python-dotenv requests numpy pandas chromadb EOF 4.升级pip和执行环境 python -m pip install --upgrade pip python -m pip install -r requirements.txt | L4: 1.openai：调用 OpenAI 模型 2.python-dotenv：读取 .env 配置文件 3.requests：发送 HTTP 请求 4.numpy：向量、矩阵、AI 数据处理 5.pandas:Excel/CSV/数据清洗 6.chromadb:向量数据库 场景是RAG、私人知识库、文档检索
A5: 4 | B5: 46254 | C5: 周四 | D5: 阶段1 环境与Python | E5: Python：变量、字符串、List/Dict/Set；完成10个小练习 | F5: 2–3小时 | G5: 已完成 | I5: =IF(G5="已完成",1,IF(G5="进行中",0.5,0)) -> 1
A6: 5 | B6: 46255 | C6: 周五 | D6: 阶段1 环境与Python | E6: Python：if/for/函数；把一个Java小逻辑改写成Python | F6: 2–3小时 | G6: 已完成 | I6: =IF(G6="已完成",1,IF(G6="进行中",0.5,0)) -> 1 | J6: def 可以返回多个 （tuple 元祖） 基础语法练习 | K6: 51
A7: 6 | B7: 46258 | C7: 周一 | D7: 阶段1 环境与Python | E7: Python：class、模块、异常；写OrderService Console | F7: 2–3小时 | G7: 已完成 | I7: =IF(G7="已完成",1,IF(G7="进行中",0.5,0)) -> 1 | K7: 51
A8: 7 | B8: 46259 | C8: 周二 | D8: 阶段1 环境与Python | E8: 文件/JSON：订单增删改查并保存到orders.json | F8: 2–3小时 | G8: 已完成 | I8: =IF(G8="已完成",1,IF(G8="进行中",0.5,0)) -> 1 | J8: _init_ self | K8: 51
A9: 8 | B9: 46260 | C9: 周三 | D9: 阶段1 环境与Python | E9: HTTP：httpx/requests；Console调用测试API并处理异常 | F9: 2–3小时 | G9: 已完成 | I9: =IF(G9="已完成",1,IF(G9="进行中",0.5,0)) -> 1 | J9: 引入协程，他是应用内管理的。OS调用前先用event loop。await是自己停止的。 await 等待时去执行其他可运行协程；如果没有可运行协程，Event Loop 等待 IO 事件，而不是强行继续当前协程。 目的：不要让一个 OS Thread 傻等一个 IO；一个线程管理大量 IO，哪个 IO Ready，就处理哪个 | K9: 51
A10: 9 | B10: 46261 | C10: 周四 | D10: 阶段1 环境与Python | E10: FastAPI/Pydantic：把订单查询暴露成REST API | F10: 2–3小时 | G10: 已完成 | I10: =IF(G10="已完成",1,IF(G10="进行中",0.5,0)) -> 1 | J10: 尾部加docs就是swaggerUI。 uvicorn main:app --reload是启动内部服务器 | K10: 51
A11: 10 | B11: 46262 | C11: 周五 | D11: 阶段1 环境与Python | E11: 【阶段验收】完成Console订单管理器 + FastAPI小服务；测试、README、复盘 | F11: 2–3小时 | G11: 已完成 | I11: =IF(G11="已完成",1,IF(G11="进行中",0.5,0)) -> 1 | J11: 安装配置：pip install python-dotenv | K11: 【阶段目标】稳定Mac开发环境；能独立写Python脚本和FastAPI接口 【验收项目】Console订单管理器 + FastAPI小服务 【验收标准】能从终端运行；JSON保存/读取；至少3个REST接口；README写清启动方式
A12: 11 | B12: 46265 | C12: 周一 | D12: 阶段2 LLM API基础 | E12: 准备模型API Key；使用环境变量/.env管理密钥 | F12: 2–3小时 | G12: 已完成 | I12: =IF(G12="已完成",1,IF(G12="进行中",0.5,0)) -> 1 | K12: 51
A13: 12 | B13: 46266 | C13: 周二 | D13: 阶段2 LLM API基础 | E13: 完成第一个LLM Console调用：输入问题→输出答案 | F13: 2–3小时 | G13: 已完成 | I13: =IF(G13="已完成",1,IF(G13="进行中",0.5,0)) -> 1 | K13: 51
A14: 13 | B14: 46267 | C14: 周三 | D14: 阶段2 LLM API基础 | E14: 实验Token、上下文、temperature等参数并记录差异 | F14: 2–3小时 | G14: 已完成 | I14: =IF(G14="已完成",1,IF(G14="进行中",0.5,0)) -> 1 | J14: temperature是随机性，大部分默认是1。 模型没有长期记忆，需要传入历史messages。 openai记录到了服务端，搜索在重新拼成需要的上下文。 | K14: 51
A15: 14 | B15: 46268 | C15: 周四 | D15: 阶段2 LLM API基础 | E15: Prompt练习：角色/目标/约束/示例；同一任务写3版 | F15: 2–3小时 | G15: 已完成 | I15: =IF(G15="已完成",1,IF(G15="进行中",0.5,0)) -> 1 | J15: Prompt = 给模型的任务说明书。Prompt:Role（角色）Goal（目标）Context（背景）Constraint（约束）Example（示例）Output Format（输出格式）。角色就是告诉模型我是谁，目标就是我要什么，约束就是条件，比如1000字以内。示例是最强的，少样本学习。 | K15: 51
A16: 15 | B16: 46269 | C16: 周五 | D16: 阶段2 LLM API基础 | E16: 结构化输出：Pydantic校验模型JSON结果 | F16: 2–3小时 | G16: 已完成 | I16: =IF(G16="已完成",1,IF(G16="进行中",0.5,0)) -> 1 | J16: 格式化成json | K16: 51
A17: 16 | B17: 46272 | C17: 周一 | D17: 阶段2 LLM API基础 | E17: 加入超时、限流、网络异常和重试 | F17: 2–3小时 | G17: 已完成 | I17: =IF(G17="已完成",1,IF(G17="进行中",0.5,0)) -> 1 | J17: rating重试 sleep | K17: 51
A18: 17 | B18: 46273 | C18: 周二 | D18: 阶段2 LLM API基础 | E18: 实现Streaming Console输出 | F18: 2–3小时 | G18: 已完成 | I18: =IF(G18="已完成",1,IF(G18="进行中",0.5,0)) -> 1 | J18: stream=True chunk.choices[0].delta.content print(..., end="", flush=True) | K18: 51
A19: 18 | B19: 46274 | C19: 周三 | D19: 阶段2 LLM API基础 | E19: 实现简单多轮对话history和上下文裁剪 | F19: 2–3小时 | G19: 已完成 | I19: =IF(G19="已完成",1,IF(G19="进行中",0.5,0)) -> 1 | J19: 通过list add和控制次数。控制总token和单次msg数据大小，太大可以top(0)弹出最旧的数据。 可以吧多次记录压缩成摘要，让 LLM 帮你压缩旧上下文。 | K19: 51
A20: 19 | B20: 46275 | C20: 周四 | D20: 阶段2 LLM API基础 | E20: 做Java异常分析助手：异常栈→原因/方案/风险JSON | F20: 2–3小时 | G20: 已完成 | I20: =IF(G20="已完成",1,IF(G20="进行中",0.5,0)) -> 1 | J20: 通过LLM来异常，非重点过了一下 | K20: 51
A21: 20 | B21: 46276 | C21: 周五 | D21: 阶段2 LLM API基础 | E21: 【阶段验收】完成AI Console/Java异常分析助手；准备5个测试案例 | F21: 2–3小时 | G21: 已完成 | I21: =IF(G21="已完成",1,IF(G21="进行中",0.5,0)) -> 1 | K21: 【阶段目标】掌握模型API、Prompt、上下文、流式输出和结构化输出 【验收项目】AI Console助手 / Java异常分析助手 【验收标准】支持连续提问；结构化JSON输出；Streaming；异常/超时处理
A22: 21 | B22: 46279 | C22: 周一 | D22: 阶段3 Tool Calling | E22: 理解Tool Calling流程；做calculator工具 | F22: 2–3小时 | G22: 已完成 | I22: =IF(G22="已完成",1,IF(G22="进行中",0.5,0)) -> 1 | J22: 程序事先不知道用户想调用哪个函数，也不知道参数是什么，让 LLM 来判断。 Agent 不是比普通程序“更高级”，而是用更高的复杂度，换取更强的自然语言理解和动态决策能力 | K22: 51
A23: 22 | B23: 46280 | C23: 周二 | D23: 阶段3 Tool Calling | E23: 实现get_order(order_id)模拟Tool | F23: 2–3小时 | G23: 已完成 | I23: =IF(G23="已完成",1,IF(G23="进行中",0.5,0)) -> 1 | J23: tool格式用的ds和openai，但是cc或者其他产商可能不一致。还要做兼容可能，主要看你llm | K23: 51
A24: 23 | B24: 46281 | C24: 周三 | D24: 阶段3 Tool Calling | E24: get_order接真实测试数据库 | F24: 2–3小时 | G24: 已完成 | I24: =IF(G24="已完成",1,IF(G24="进行中",0.5,0)) -> 1 | J24: 自然语言 ↓ LLM翻译成：函数名 + 参数 ↓ tool_map 找函数 ↓ func(**arguments) 真正执行 | K24: 51
A25: 24 | B25: 46282 | C25: 周四 | D25: 阶段3 Tool Calling | E25: 实现get_user Tool | F25: 2–3小时 | G25: 已完成 | I25: =IF(G25="已完成",1,IF(G25="进行中",0.5,0)) -> 1 | K25: 51
A26: 25 | B26: 46283 | C26: 周五 | D26: 阶段3 Tool Calling | E26: 实现get_payment Tool | F26: 2–3小时 | G26: 已完成 | I26: =IF(G26="已完成",1,IF(G26="进行中",0.5,0)) -> 1 | K26: 51
A27: 26 | B27: 46286 | C27: 周一 | D27: 阶段3 Tool Calling | E27: 实现get_refund Tool | F27: 2–3小时 | G27: 已完成 | I27: =IF(G27="已完成",1,IF(G27="进行中",0.5,0)) -> 1 | K27: 51
A28: 27 | B28: 46287 | C28: 周二 | D28: 阶段3 Tool Calling | E28: 统一Tool参数和返回结构 | F28: 2–3小时 | G28: 已完成 | I28: =IF(G28="已完成",1,IF(G28="进行中",0.5,0)) -> 1 | K28: 51
A29: 28 | B29: 46288 | C29: 周三 | D29: 阶段3 Tool Calling | E29: 实现Tool Dispatcher/Registry | F29: 2–3小时 | G29: 已完成 | I29: =IF(G29="已完成",1,IF(G29="进行中",0.5,0)) -> 1 | K29: 51
A30: 29 | B30: 46289 | C30: 周四 | D30: 阶段3 Tool Calling | E30: 完成单次Tool闭环：LLM→Tool→LLM | F30: 2–3小时 | G30: 已完成 | I30: =IF(G30="已完成",1,IF(G30="进行中",0.5,0)) -> 1 | K30: 51
A31: 30 | B31: 46293 | C31: 周一 | D31: 阶段3 Tool Calling | E31: 完成多Tool连续调用 | F31: 2–3小时 | G31: 已完成 | I31: =IF(G31="已完成",1,IF(G31="进行中",0.5,0)) -> 1 | K31: 51
A32: 31 | B32: 46294 | C32: 周二 | D32: 阶段3 Tool Calling | E32: 增加Tool超时和异常捕获 | F32: 2–3小时 | G32: 已完成 | I32: =IF(G32="已完成",1,IF(G32="进行中",0.5,0)) -> 1 | J32: with ThreadPoolExecutor和ThreadPoolExecutor，with要等主线程执行完毕。如果里面是 future = executor.submit( tool_func, **arguments ) | K32: 51
A33: 32 | B33: 46295 | C33: 周三 | D33: 阶段3 Tool Calling | E33: 记录工具名/参数/耗时/状态日志 | F33: 2–3小时 | G33: 已完成 | I33: =IF(G33="已完成",1,IF(G33="进行中",0.5,0)) -> 1 | K33: 51
A34: 33 | B34: 46303 | C34: 周四 | D34: 阶段3 Tool Calling | E34: 增加工具白名单；禁止任意SQL | F34: 2–3小时 | G34: 已完成 | I34: =IF(G34="已完成",1,IF(G34="进行中",0.5,0)) -> 1 | K34: 51
A35: 34 | B35: 46304 | C35: 周五 | D35: 阶段3 Tool Calling | E35: 完成订单退款失败分析助手 | F35: 2–3小时 | G35: 已完成 | I35: =IF(G35="已完成",1,IF(G35="进行中",0.5,0)) -> 1 | K35: 51
A36: 35 | B36: 46307 | C36: 周一 | D36: 阶段3 Tool Calling | E36: 【阶段验收】用10个问题测试工具选择和多步调用；整理README | F36: 2–3小时 | G36: 已完成 | I36: =IF(G36="已完成",1,IF(G36="进行中",0.5,0)) -> 1 | J36: 涉及到Agent 编排 / Guardrail 核心是：56～70 Guardrail会在97 | K36: 【阶段目标】让模型可靠调用数据库/API工具完成业务查询 【验收项目】订单退款失败分析助手 【验收标准】至少4个Tools；能自动选工具；支持连续工具调用；有调用日志和错误处理
A37: 36 | B37: 46308 | C37: 周二 | D37: 阶段4 RAG知识库 | E37: 理解RAG链路；画出自己的RAG流程图 | F37: 2–3小时 | G37: 已完成 | I37: =IF(G37="已完成",1,IF(G37="进行中",0.5,0)) -> 1 | J37: 参考流程图。Overlap 上下chunk关联。 | K37: 51
A38: 37 | B38: 46309 | C38: 周三 | D38: 阶段4 RAG知识库 | E38: 安装Docker Desktop；确认docker compose可用 | F38: 2–3小时 | G38: 已完成 | I38: =IF(G38="已完成",1,IF(G38="进行中",0.5,0)) -> 1 | K38: 51
A39: 38 | B39: 46310 | C39: 周四 | D39: 阶段4 RAG知识库 | E39: Docker启动PostgreSQL + pgvector | F39: 2–3小时 | G39: 已完成 | I39: =IF(G39="已完成",1,IF(G39="进行中",0.5,0)) -> 1 | J39: SELECT id, content, embedding, embedding <=> '[0.85,0.15,0.25]' AS distance FROM rag_documents ORDER BY embedding <=> '[0.85,0.15,0.25]' LIMIT 3; limit 3 就是top3。 | K39: <=> = cosine distance（余弦距离） <-> = Euclidean distance（欧氏距离） <#> = negative inner product（负内积） 1 - (embedding <=> '[0.85,0.15,0.25]') AS similarity 就是相似度，越大越相识
A40: 39 | B40: 46311 | C40: 周五 | D40: 阶段4 RAG知识库 | E40: Embedding：10段文本向量化并入库 | F40: 2–3小时 | G40: 已完成 | I40: =IF(G40="已完成",1,IF(G40="进行中",0.5,0)) -> 1 | J40: inter mac： Python 3.11 numpy 1.26.4 torch 2.2.2 transformers 4.41.2 sentence-transformers 3.0.1 | K40: 51
...

Sheet Mac环境清单
A1: 顺序 | B1: 环境/软件 | C1: 用途 | D1: 安装阶段 | E1: 要求
A2: 1 | B2: Homebrew | C2: Mac软件包管理 | D2: 第1天 | E2: 已有则检查版本
A3: 2 | B3: Git | C3: 代码管理 | D3: 第1天 | E3: 确认可用
A4: 3 | B4: VS Code | C4: Python/AI主IDE | D4: 第1天 | E4: 确认可用
A5: 4 | B5: Python 3.11/3.12 | C5: AI主语言 | D5: 第1周 | E5: venv隔离
A6: 5 | B6: IntelliJ IDEA | C6: Java/Spring Boot | D6: 第1天检查 | E6: 保留现有环境
A7: 6 | B7: JDK 17/21 | C7: Spring AI | D7: 阶段7前 | E7: 与旧JDK隔离
A8: 7 | B8: Docker Desktop | C8: pgvector/Redis | D8: 阶段4 | E8: 学到RAG再装
A9: 8 | B9: PostgreSQL + pgvector | C9: RAG向量库 | D9: 阶段4 | E9: Docker启动
A10: 9 | B10: Postman/curl | C10: 接口测试 | D10: 按需 | E10: 任选
A11: 10 | B11: Node.js LTS | C11: 最终项目前端 | D11: 阶段8 | E11: 前期不必安装
A12: 11 | B12: Windows台式机 | C12: 辅助部署/本地模型 | D12: 后期 | E12: 前3个月不作为重点

Sheet 进度总览
A1: AI Agent 学习进度总览
A3: 指标 | B3: 数值 | D3: 指标 | E3: 数值
A4: 计划学习日 | B4: 100 | D4: 进行中 | E4: =COUNTIF(每日学习计划!G2:G102,"进行中") -> 2
A5: 计划总时长 | B5: 200–300小时 | D5: 顺延 | E5: =COUNTIF(每日学习计划!G2:G102,"顺延") -> 0
A6: 开始日期 | B6: 46251 | D6: 整体完成度 | E6: =AVERAGE(每日学习计划!I2:I102) -> 0.545
A7: 结束日期 | B7: 46399 | D7: 实际学习小时 | E7: =SUM(每日学习计划!H2:H102) -> 0
A8: 已完成天数 | B8: =COUNTIF(每日学习计划!G2:G102,"已完成") -> 54 | D8: 剩余学习日 | E8: =100-B8 -> 46

Sheet RAG相关
